Workbook

Sheet Posts
A1: PostID | B1: Platform | C1: Date | D1: ContentType | E1: Hashtags | F1: Separate Hashtag | G1: Likes | H1: Shares | I1: Comments | J1: Clicks | K1: Reach | L1: Impressions | M1: Engagement Rate | N1: Total Engagement | O1: Post Interaction Rate | P1: Campaign
A2: A1 | B2: YouTube | C2: 2024-12-23 | D2: Image | E2: #AppleWatchUltra2 #HealthTech | F2: AppleWatchUltra2 HealthTech | G2: 24516 | H2: 976 | I2: 974 | J2: 2675 | K2: 23275 | L2: 202932 | M2: 25492.005 | N2: 29141 | O2: 14.359983 | P2: Apple Watch Ultra 2 Launch | FH2: AppleWatchUltra2 | FI2: HealthTech
A3: A2 | B3: LinkedIn | C3: 45903 | D3: Image | E3: #MacBookAirM3 #AppleInnovation | F3: MacBookAirM3 AppleInnovation | G3: 4779 | H3: 1110 | I3: 436 | J3: 1574 | K3: 77167 | L3: 71585 | M3: 5889.0061 | N3: 7899 | O3: 11.034435 | P3: Apple Event September 2025
A4: A3 | B4: Instagram | C4: 2025-05-12 | D4: Tweet | E4: #AppleDesign #Innovation | F4: AppleDesign Innovation | G4: 19308 | H4: 1318 | I4: 795 | J4: 1499 | K4: 52307 | L4: 193087 | M4: 20626.004 | N4: 22920 | O4: 11.870297 | P4: Sustainability Awareness Drive
A5: A4 | B5: YouTube | C5: 2024-08-12 | D5: Video | E5: #AppleEvent #iPadPro | F5: AppleEvent iPadPro | G5: 3581 | H5: 517 | I5: 880 | J5: 1925 | K5: 18636 | L5: 248611 | M5: 4098.0035 | N5: 6903 | O5: 2.7766269 | P5: iPhone 16 Launch
A6: A5 | B6: YouTube | C6: 45904 | D6: Video | E6: #AppleWatchUltra2 #HealthTech | F6: AppleWatchUltra2 HealthTech | G6: 21708 | H6: 435 | I6: 317 | J6: 1213 | K6: 70701 | L6: 83585 | M6: 22143.004 | N6: 23673 | O6: 28.322067 | P6: Apple Event September 2025
A7: A6 | B7: LinkedIn | C7: 45905 | D7: Image | E7: #ShotOniPhone | F7: ShotOniPhone | G7: 14677 | H7: 533 | I7: 759 | J7: 753 | K7: 23275 | L7: 66958 | M7: 15210.011 | N7: 16722 | O7: 24.973864 | P7: Apple Event September 2025
A8: A7 | B8: Instagram | C8: 2024-06-24 | D8: Carousel | E8: #AppleMusic #AppleLifestyle | F8: AppleMusic AppleLifestyle | G8: 7713 | H8: 575 | I8: 417 | J8: 336 | K8: 61660 | L8: 66017 | M8: 8288.0063 | N8: 9041 | O8: 13.694957 | P8: iPhone 16 Launch
A9: A8 | B9: Instagram | C9: 2024-07-13 | D9: Video | E9: #AppleWatch #Health | F9: AppleWatch Health | G9: 18639 | H9: 1360 | I9: 898 | J9: 2011 | K9: 42841 | L9: 247779 | M9: 19999.004 | N9: 22908 | O9: 9.2453356 | P9: iPhone 16 Launch
A10: A9 | B10: YouTube | C10: 2024-08-30 | D10: Carousel | E10: #MacBookAirM3 #AppleInnovation | F10: MacBookAirM3 AppleInnovation | G10: 6804 | H10: 787 | I10: 970 | J10: 1095 | K10: 56343 | L10: 164677 | M10: 7591.0059 | N10: 9656 | O10: 5.8635997 | P10: Apple Watch Ultra 2 Launch
A11: A10 | B11: Twitter | C11: 2025-03-11 | D11: Video | E11: #iPhone16Launch #AppleEvent | F11: iPhone16Launch AppleEvent | G11: 20222 | H11: 712 | I11: 604 | J11: 1272 | K11: 71598 | L11: 216422 | M11: 20934.003 | N11: 22810 | O11: 10.539594 | P11: Sustainability Awareness Drive
A12: A11 | B12: YouTube | C12: 2025-02-02 | D12: Carousel | E12: #AppleEvent #iPadPro | F12: AppleEvent iPadPro | G12: 12136 | H12: 1117 | I12: 834 | J12: 892 | K12: 24675 | L12: 183273 | M12: 13253.005 | N12: 14979 | O12: 8.1730533 | P12: Sustainability Awareness Drive
A13: A12 | B13: YouTube | C13: 2024-07-21 | D13: Tweet | E13: #MacBookAirM3 #AppleInnovation | F13: MacBookAirM3 AppleInnovation | G13: 2009 | H13: 1072 | I13: 550 | J13: 1437 | K13: 22982 | L13: 69426 | M13: 3081.0079 | N13: 5068 | O13: 7.2998588 | P13: iPhone 16 Launch
A14: A13 | B14: YouTube | C14: 2024-11-18 | D14: Carousel | E14: #AppleMusic #AppleLifestyle | F14: AppleMusic AppleLifestyle | G14: 21255 | H14: 1452 | I14: 625 | J14: 1624 | K14: 21282 | L14: 57778 | M14: 22707.011 | N14: 24956 | O14: 43.192911 | P14: MacBook Air M3 Campaign
A15: A14 | B15: YouTube | C15: 45906 | D15: Tweet | E15: #AppleWatch #Health | F15: AppleWatch Health | G15: 7124 | H15: 469 | I15: 851 | J15: 2571 | K15: 33802 | L15: 216313 | M15: 7593.0039 | N15: 11015 | O15: 5.0921581 | P15: Apple Event September 2025
A16: A15 | B16: LinkedIn | C16: 45907 | D16: Tweet | E16: #AppleDesign #Innovation | F16: AppleDesign Innovation | G16: 3015 | H16: 997 | I16: 783 | J16: 617 | K16: 77167 | L16: 82229 | M16: 4012.0095 | N16: 5412 | O16: 6.5816196 | P16: Apple Event September 2025
A17: A16 | B17: Instagram | C17: 2024-08-26 | D17: Carousel | E17: #AppleWatch #Health | F17: AppleWatch Health | G17: 4193 | H17: 924 | I17: 707 | J17: 2696 | K17: 55075 | L17: 126652 | M17: 5117.0056 | N17: 8520 | O17: 6.7270947 | P17: iPhone 16 Launch
A18: A17 | B18: LinkedIn | C18: 2025-05-05 | D18: Tweet | E18: #AppleEvent #iPhone16 | F18: AppleEvent iPhone16 | G18: 10415 | H18: 1388 | I18: 725 | J18: 2462 | K18: 53082 | L18: 168267 | M18: 11803.004 | N18: 14990 | O18: 8.908461 | P18: MacBook Air M3 Campaign
A19: A18 | B19: LinkedIn | C19: 2024-08-19 | D19: Image | E19: #AppleWatch #Health | F19: AppleWatch Health | G19: 15550 | H19: 204 | I19: 279 | J19: 1646 | K19: 35819 | L19: 219436 | M19: 15754.001 | N19: 17679 | O19: 8.0565632 | P19: Apple Watch Ultra 2 Launch
A20: A19 | B20: LinkedIn | C20: 2024-06-23 | D20: Tweet | E20: #AppleEvent #iPhone16 | F20: AppleEvent iPhone16 | G20: 16512 | H20: 1050 | I20: 971 | J20: 1891 | K20: 15865 | L20: 166503 | M20: 17562.006 | N20: 20424 | O20: 12.266446 | P20: iPhone 16 Launch
A21: A20 | B21: YouTube | C21: 2024-09-09 | D21: Video | E21: #AppleDesign #Innovation | F21: AppleDesign Innovation | G21: 6158 | H21: 277 | I21: 512 | J21: 2189 | K21: 76881 | L21: 124878 | M21: 6435.0041 | N21: 9136 | O21: 7.3159404 | P21: iPhone 16 Launch
A22: A21 | B22: Twitter | C22: 45908 | D22: Carousel | E22: #iPhonePhotography #ShotOniPhone | F22: iPhonePhotography ShotOniPhone | G22: 22309 | H22: 773 | I22: 854 | J22: 2387 | K22: 72396 | L22: 97056 | M22: 23082.009 | N22: 26323 | O22: 27.121456 | P22: Apple Event September 2025
A23: A22 | B23: Instagram | C23: 2025-02-27 | D23: Image | E23: #AppleMusic #AppleLifestyle | F23: AppleMusic AppleLifestyle | G23: 8970 | H23: 331 | I23: 968 | J23: 2296 | K23: 24613 | L23: 198562 | M23: 9301.0049 | N23: 12565 | O23: 6.3279983 | P23: iPhone 16 Launch
A24: A23 | B24: Twitter | C24: 2024-11-06 | D24: Carousel | E24: #AppleEvent #iPhone16 | F24: AppleEvent iPhone16 | G24: 8938 | H24: 800 | I24: 842 | J24: 2072 | K24: 31736 | L24: 59975 | M24: 9738.014 | N24: 12652 | O24: 21.095456 | P24: iPhone 16 Launch
A25: A24 | B25: LinkedIn | C25: 2025-01-23 | D25: Video | E25: #iPhone16Launch #AppleEvent | F25: iPhone16Launch AppleEvent | G25: 23168 | H25: 1265 | I25: 441 | J25: 1612 | K25: 66615 | L25: 197795 | M25: 24433.002 | N25: 26486 | O25: 13.390632 | P25: iPhone 16 Launch
A26: A25 | B26: LinkedIn | C26: 45909 | D26: Video | E26: #AppleWatch #Health | F26: AppleWatch Health | G26: 15772 | H26: 288 | I26: 520 | J26: 1585 | K26: 59182 | L26: 194351 | M26: 16060.003 | N26: 18165 | O26: 9.3464917 | P26: Apple Event September 2025
A27: A26 | B27: Twitter | C27: 2025-04-05 | D27: Video | E27: #AppleWatch #Health | F27: AppleWatch Health | G27: 22384 | H27: 601 | I27: 943 | J27: 515 | K27: 41309 | L27: 249373 | M27: 22985.004 | N27: 24443 | O27: 9.8017829 | P27: Apple Watch Ultra 2 Launch
A28: A27 | B28: Twitter | C28: 2024-09-17 | D28: Tweet | E28: #iPhone16Launch #AppleEvent | F28: iPhone16Launch AppleEvent | G28: 20017 | H28: 495 | I28: 178 | J28: 2683 | K28: 32244 | L28: 182633 | M28: 20512.001 | N28: 23373 | O28: 12.797797 | P28: Apple Watch Ultra 2 Launch
A29: A28 | B29: Twitter | C29: 2025-03-04 | D29: Tweet | E29: #ShotOniPhone | F29: ShotOniPhone | G29: 12344 | H29: 815 | I29: 298 | J29: 2439 | K29: 6259 | L29: 237133 | M29: 13159.001 | N29: 15896 | O29: 6.7034112 | P29: iPhone 16 Launch
A30: A29 | B30: LinkedIn | C30: 45910 | D30: Carousel | E30: #MacBookProM3 | F30: MacBookProM3 | G30: 9266 | H30: 999 | I30: 928 | J30: 2700 | K30: 12264 | L30: 128397 | M30: 10265.007 | N30: 13893 | O30: 10.820346 | P30: Apple Event September 2025
A31: A30 | B31: LinkedIn | C31: 2025-02-25 | D31: Carousel | E31: #iPhonePhotography #ShotOniPhone | F31: iPhonePhotography ShotOniPhone | G31: 10702 | H31: 621 | I31: 445 | J31: 2918 | K31: 54808 | L31: 220225 | M31: 11323.002 | N31: 14686 | O31: 6.6686344 | P31: Apple Watch Ultra 2 Launch
A32: A31 | B32: Instagram | C32: 2024-12-16 | D32: Image | E32: #AppleEvent #iPadPro | F32: AppleEvent iPadPro | G32: 2384 | H32: 1246 | I32: 160 | J32: 2004 | K32: 2701 | L32: 73142 | M32: 3630.0022 | N32: 5794 | O32: 7.9215772 | P32: Apple Watch Ultra 2 Launch
A33: A32 | B33: Instagram | C33: 2024-07-31 | D33: Image | E33: #AppleEvent #iPhone16 | F33: AppleEvent iPhone16 | G33: 2404 | H33: 774 | I33: 661 | J33: 662 | K33: 12676 | L33: 66916 | M33: 3178.0099 | N33: 4501 | O33: 6.7263435 | P33: Apple Watch Ultra 2 Launch
A34: A33 | B34: LinkedIn | C34: 45911 | D34: Carousel | E34: #iPhone16Launch #AppleEvent | F34: iPhone16Launch AppleEvent | G34: 10175 | H34: 342 | I34: 825 | J34: 2904 | K34: 15954 | L34: 104324 | M34: 10517.008 | N34: 14246 | O34: 13.655535 | P34: Apple Event September 2025
A35: A34 | B35: Twitter | C35: 45912 | D35: Tweet | E35: #AppleDesign #Innovation | F35: AppleDesign Innovation | G35: 17158 | H35: 1192 | I35: 262 | J35: 2016 | K35: 28771 | L35: 216037 | M35: 18350.001 | N35: 20628 | O35: 9.5483644 | P35: Apple Event September 2025
A36: A35 | B36: Twitter | C36: 2024-11-30 | D36: Video | E36: #AppleEvent #iPhone16 | F36: AppleEvent iPhone16 | G36: 14763 | H36: 864 | I36: 336 | J36: 1493 | K36: 33310 | L36: 165932 | M36: 15627.002 | N36: 17456 | O36: 10.519972 | P36: iPhone 16 Launch
A37: A36 | B37: Instagram | C37: 2025-04-19 | D37: Carousel | E37: #MacBookProM3 | F37: MacBookProM3 | G37: 20384 | H37: 344 | I37: 956 | J37: 655 | K37: 67621 | L37: 175720 | M37: 20728.005 | N37: 22339 | O37: 12.712839 | P37: Sustainability Awareness Drive
A38: A37 | B38: LinkedIn | C38: 2025-01-06 | D38: Image | E38: #AppleDesign #Innovation | F38: AppleDesign Innovation | G38: 11860 | H38: 1448 | I38: 893 | J38: 490 | K38: 23518 | L38: 206205 | M38: 13308.004 | N38: 14691 | O38: 7.1244635 | P38: Apple Watch Ultra 2 Launch
A39: A38 | B39: Instagram | C39: 2025-02-17 | D39: Tweet | E39: #MacBookAirM3 #AppleInnovation | F39: MacBookAirM3 AppleInnovation | G39: 7989 | H39: 1206 | I39: 376 | J39: 2769 | K39: 27550 | L39: 221749 | M39: 9195.0017 | N39: 12340 | O39: 5.5648503 | P39: Sustainability Awareness Drive
A40: A39 | B40: Instagram | C40: 45913 | D40: Carousel | E40: #AppleMusic #AppleLifestyle | F40: AppleMusic AppleLifestyle | G40: 17106 | H40: 702 | I40: 459 | J40: 999 | K40: 59627 | L40: 136059 | M40: 17808.003 | N40: 19266 | O40: 14.160034 | P40: Apple Event September 2025
...

Sheet Engagement Summary
A1: Month | B1: Week_Start_Date | C1: Platform | D1: New_Followers | E1: Unfollows | F1: Total_Followers | G1: Engagement_Rate | H1: Ad_Spend | I1: Engagement | J1: Cost per new follower | K1: ROI | L1: Net followers
A2: Jun | B2: 2024-06-03 | C2: Instagram | D2: 4138 | E2: 361 | F2: 103777 | G2: 56.637791 | H2: 23944 | I2: 5877700 | J2: =H2/D2 -> 5.7863702 | K2: =I2/H2 -> 245.47695 | L2: =D2-E2 -> 3777
A3: Jun | B3: 2024-06-03 | C3: Twitter | D3: 8693 | E3: 1261 | F3: 111209 | G3: 69.475492 | H3: 29873 | I3: 7726300 | J3: =H3/D3 -> 3.4364431 | K3: =I3/H3 -> 258.63824 | L3: =D3-E3 -> 7432
A4: Jun | B4: 2024-06-03 | C4: YouTube | D4: 9264 | E4: 1141 | F4: 119332 | G4: 92.312205 | H4: 50372 | I4: 11015800 | J4: =H4/D4 -> 5.4373921 | K4: =I4/H4 -> 218.68895 | L4: =D4-E4 -> 8123
A5: Jun | B5: 2024-06-03 | C5: YouTube | D5: 8842 | E5: 971 | F5: 127203 | G5: 16.351816 | H5: 33928 | I5: 2080000 | J5: =H5/D5 -> 3.8371409 | K5: =I5/H5 -> 61.306296 | L5: =D5-E5 -> 7871
A6: Jun | B6: 2024-06-10 | C6: Instagram | D6: 7721 | E6: 506 | F6: 134418 | G6: 35.577824 | H6: 25379 | I6: 4782300 | J6: =H6/D6 -> 3.2870095 | K6: =I6/H6 -> 188.43532 | L6: =D6-E6 -> 7215
A7: Jun | B7: 2024-06-10 | C7: YouTube | D7: 8002 | E7: 524 | F7: 141896 | G7: 52.064893 | H7: 46751 | I7: 7387800 | J7: =H7/D7 -> 5.8424144 | K7: =I7/H7 -> 158.02443 | L7: =D7-E7 -> 7478
A8: Jun | B8: 2024-06-10 | C8: Twitter | D8: 5225 | E8: 291 | F8: 146830 | G8: 19.551863 | H8: 44546 | I8: 2870800 | J8: =H8/D8 -> 8.5255502 | K8: =I8/H8 -> 64.445741 | L8: =D8-E8 -> 4934
A9: Jun | B9: 2024-06-10 | C9: Twitter | D9: 3978 | E9: 543 | F9: 150265 | G9: 49.159818 | H9: 34286 | I9: 7387000 | J9: =H9/D9 -> 8.618904 | K9: =I9/H9 -> 215.45237 | L9: =D9-E9 -> 3435
A10: Jun | B10: 2024-06-17 | C10: Instagram | D10: 8373 | E10: 921 | F10: 157717 | G10: 12.226329 | H10: 15110 | I10: 1928300 | J10: =H10/D10 -> 1.8046101 | K10: =I10/H10 -> 127.61747 | L10: =D10-E10 -> 7452
A11: Jun | B11: 2024-06-17 | C11: Twitter | D11: 6907 | E11: 834 | F11: 163790 | G11: 54.158984 | H11: 22087 | I11: 8870700 | J11: =H11/D11 -> 3.1977704 | K11: =I11/H11 -> 401.62539 | L11: =D11-E11 -> 6073
A12: Jun | B12: 2024-06-17 | C12: LinkedIn | D12: 7097 | E12: 369 | F12: 170518 | G12: 9.2506363 | H12: 33762 | I12: 1577400 | J12: =H12/D12 -> 4.7572214 | K12: =I12/H12 -> 46.721166 | L12: =D12-E12 -> 6728
A13: Jun | B13: 2024-06-17 | C13: Instagram | D13: 6656 | E13: 978 | F13: 176196 | G13: 60.425889 | H13: 27081 | I13: 10646800 | J13: =H13/D13 -> 4.0686599 | K13: =I13/H13 -> 393.14649 | L13: =D13-E13 -> 5678
... A201: May | B201: 2025-05-12 | C201: Twitter | D201: 8527 | E201: 1091 | F201: 1186398 | G201: 1.6760817 | H201: 41703 | I201: 1988500 | J201: =H201/D201 -> 4.8907001 | K201: =I201/H201 -> 47.682421 | L201: =D201-E201 -> 7436

Sheet Campaign Metadata
A1: Campaign_Name | B1: Start_Date | C1: End_Date | D1: Objective | E1: Ad_Spend | F1: Impressions | G1: Engagement_Uplift | H1: Engagement During Campaign | I1: Engagement Before Campaign | J1: Calculated Engagement Uplift (%) | K1: Net follower growth | L1: Engagement
A2: iPhone 16 Launch | B2: 2024-06-15 | C2: 2024-07-15 | D2: Product Launch | E2: 85000 | F2: 950000 | G2: 0.45 | H2: 0 | I2: 0 | J2: =(H2-I2)/I2 -> #DIV/0! | L2: 926462 | M2: {=SUMPRODUCT(('Engagement Summary'!$D:$D)*('Engagement Summary'!$B:$B>='Campaign Metadata'!B2)*('Engagement Summary'!$B:$B <('Campaign Metadata'!C2+1)))} -> #VALUE!
A3: MacBook Air M3 Campaign | B3: 2024-10-01 | C3: 2024-10-31 | D3: Product Promotion | E3: 60000 | F3: 780000 | G3: 0.38 | H3: 0 | I3: 0 | J3: =(H3-I3)/I3 -> #DIV/0! | L3: 652233 | M3: {=SUMPRODUCT(('Engagement Summary'!$D:$D)*('Engagement Summary'!$B:$B>='Campaign Metadata'!B3)*('Engagement Summary'!$B:$B <('Campaign Metadata'!C3+1)))} -> #VALUE!
A4: Apple Watch Ultra 2 Launch | B4: 2024-12-25 | C4: 2025-01-10 | D4: Health & Fitness Awareness | E4: 55000 | F4: 700000 | G4: 0.41 | H4: 0 | I4: 0 | J4: =(H4-I4)/I4 -> #DIV/0! | L4: 991433 | M4: {=SUMPRODUCT(('Engagement Summary'!$D:$D)*('Engagement Summary'!$B:$B>='Campaign Metadata'!B4)*('Engagement Summary'!$B:$B <('Campaign Metadata'!C4+1)))} -> #VALUE!
A5: Sustainability Awareness Drive | B5: 2025-03-01 | C5: 2025-03-31 | D5: Sustainability Branding | E5: 40000 | F5: 550000 | G5: 0.32 | H5: 0 | I5: 0 | J5: =(H5-I5)/I5 -> #DIV/0! | L5: 879891 | M5: {=SUMPRODUCT(('Engagement Summary'!$D:$D)*('Engagement Summary'!$B:$B>='Campaign Metadata'!B5)*('Engagement Summary'!$B:$B <('Campaign Metadata'!C5+1)))} -> #VALUE!
A6: Apple Event September 2025 | B6: 45901 | C6: 45930 | D6: Brand Engagement | E6: 75000 | F6: 880000 | G6: 0.47 | H6: 918031 | I6: 0 | J6: =H6-I6/I6 -> #DIV/0! | L6: 1051098 | M6: {=SUMPRODUCT(('Engagement Summary'!$D:$D)*('Engagement Summary'!$B:$B>='Campaign Metadata'!B6)*('Engagement Summary'!$B:$B <('Campaign Metadata'!C6+1)))} -> #VALUE!

Sheet Top 10 posts with hih engageme
A1: Row Labels | B1: Sum of Engagement
A2: A1 | B2: 26466
A3: A104 | B3: 26469
A4: A109 | B4: 26128
A5: A127 | B5: 26206
A6: A139 | B6: 25774
A7: A153 | B7: 25763
A8: A157 | B8: 25652
A9: A268 | B9: 26026
A10: A47 | B10: 26198
A11: A72 | B11: 25907
A12: Grand Total | B12: 260589

Sheet Total likes,Share and comment
B1: Column Labels
B2: Carousel | E2: Image | H2: Tweet | K2: Video | N2: Total Sum of Likes | O2: Total Sum of Comments | P2: Total Sum of Shares
A3: Row Labels | B3: Sum of Likes | C3: Sum of Comments | D3: Sum of Shares | E3: Sum of Likes | F3: Sum of Comments | G3: Sum of Shares | H3: Sum of Likes | I3: Sum of Comments | J3: Sum of Shares | K3: Sum of Likes | L3: Sum of Comments | M3: Sum of Shares
A4: Instagram | B4: 278757 | C4: 13676 | D4: 16508 | E4: 218031 | F4: 10389 | G4: 18753 | H4: 206053 | I4: 9295 | J4: 14750 | K4: 244355 | L4: 7426 | M4: 13194 | N4: 947196 | O4: 40786 | P4: 63205
A5: LinkedIn | B5: 246297 | C5: 12611 | D5: 18856 | E5: 329722 | F5: 14305 | G5: 19905 | H5: 279588 | I5: 11014 | J5: 17963 | K5: 278759 | L5: 11770 | M5: 14236 | N5: 1134366 | O5: 49700 | P5: 70960
A6: Twitter | B6: 394886 | C6: 14381 | D6: 21298 | E6: 148676 | F6: 6092 | G6: 7832 | H6: 249305 | I6: 9160 | J6: 15862 | K6: 244756 | L6: 9640 | M6: 14669 | N6: 1037623 | O6: 39273 | P6: 59661
A7: YouTube | B7: 279732 | C7: 13714 | D7: 24668 | E7: 195079 | F7: 8277 | G7: 10604 | H7: 187129 | I7: 8101 | J7: 14136 | K7: 286318 | L7: 12537 | M7: 18052 | N7: 948258 | O7: 42629 | P7: 67460
A8: Grand Total | B8: 1199672 | C8: 54382 | D8: 81330 | E8: 891508 | F8: 39063 | G8: 57094 | H8: 922075 | I8: 37570 | J8: 62711 | K8: 1054188 | L8: 41373 | M8: 60151 | N8: 4067443 | O8: 172388 | P8: 261286

Sheet Average clicks per post by Hash
A1: Row Labels | B1: Average of Clicks
A2: #AppleDesign #Innovation | B2: 1592.72
A3: #AppleEvent #iPadPro | B3: 1477.2632
A4: #AppleEvent #iPhone16 | B4: 1579.4375
A5: #AppleMusic #AppleLifestyle | B5: 1463.2941
A6: #AppleWatch #Health | B6: 1711.5135
A7: #AppleWatchUltra2 #HealthTech | B7: 1674.96
A8: #iPhone16Launch #AppleEvent | B8: 1811.3103
A9: #iPhonePhotography #ShotOniPhone | B9: 1706.76
A10: #MacBookAirM3 #AppleInnovation | B10: 1680.3571
A11: #MacBookProM3 | B11: 1289.4118
A12: #ShotOniPhone | B12: 1592.9375
A13: #Sustainability #AppleEarth | B13: 1459.3077
A14: Grand Total | B14: 1606.6833

Sheet Platform with highest engagemen
A1: Sum of Engagement | B1: Column Labels
A2: Row Labels | B2: Carousel | C2: Image | D2: Tweet | E2: Video | F2: Grand Total
A3: Instagram | B3: 308941 | C3: 247173 | D3: 230098 | E3: 264975 | F3: 1051187
A4: LinkedIn | B4: 277764 | C4: 363932 | D4: 308565 | E4: 304765 | F4: 1255026
A5: Twitter | B5: 430565 | C5: 162600 | D5: 274327 | E5: 269065 | F5: 1136557
A6: YouTube | B6: 318114 | C6: 213960 | D6: 209366 | E6: 316907 | F6: 1058347
A7: Grand Total | B7: 1335384 | C7: 987665 | D7: 1022356 | E7: 1155712 | F7: 4501117
A9: Instagram,Twitter and Youtube has highest engagement in Carsousel and Linkedin has highest engagement in Image

Sheet Folower Growth rate across plat
A1: Sum of Total_Followers | B1: Column Labels
A2: Row Labels | B2: Instagram | C2: LinkedIn | D2: Twitter | E2: YouTube | F2: Grand Total
A3: Jan | B3: 1678970 | C3: 2442487 | D3: 6631554 | E3: 2462762 | F3: 13215773
A4: Feb | B4: 3749314 | C4: 3632808 | D4: 3595065 | E4: 3662672 | F4: 14639859
A5: Mar | B5: 3068302 | C5: 9209789 | D5: 4001105 | E5: 4067744 | F5: 20346940
A6: Apr | B6: 4463934 | C6: 6629107 | D6: 5654459 | E6: 1073082 | F6: 17820582
A7: May | B7: 2338827 | C7: 4669630 | D7: 1186398 | E7: 1157985 | F7: 9352840
A8: Jun | B8: 761843 | C8: 170518 | D8: 961762 | E8: 586819 | F8: 2480942
A9: Jul | B9: 950407 | C9: 2059655 | D9: 1282914 | E9: 845232 | F9: 5138208
A10: Aug | B10: 1748424 | C10: 692269 | D10: 1363921 | E10: 1776227 | F10: 5580841
A11: Sep | B11: 3575412 | C11: 1299882 | D11: 2295757 | E11: 1758174 | F11: 8929225
A12: Oct | B12: 2162853 | C12: 1663426 | D12: 1572941 | E12: 3214198 | F12: 8613418
A13: Nov | B13: 1948470 | C13: 3183897 | D13: 3063395 | E13: 1901467 | F13: 10097229
A14: Dec | B14: 4996266 | C14: 5114622 | D14: 2202932 | E14: 2151867 | F14: 14465687
A15: Grand Total | B15: 31443022 | C15: 40768090 | D15: 33812203 | E15: 24658229 | F15: 130681544

Sheet Sum of Engagement Rate
A1: Sum of Engagement Rate | B1: Column Labels
A2: Row Labels | B2: Carousel | C2: Image | D2: Tweet | E2: Video | F2: Grand Total
A3: Instagram | B3: 295265.12 | C3: 236784.09 | D3: 220803.09 | E3: 257549.08 | F3: 1010401.4
A4: LinkedIn | B4: 265153.1 | C4: 349627.12 | D4: 297551.09 | E4: 292995.1 | F4: 1205326.4
A5: Twitter | B5: 416184.13 | C5: 156508.06 | D5: 265167.08 | E5: 259425.09 | F5: 1097284.4
A6: YouTube | B6: 304400.11 | C6: 205683.06 | D6: 201265.08 | E6: 304370.11 | F6: 1015718.4
A7: Grand Total | B7: 1281002.5 | C7: 948602.32 | D7: 984786.33 | E7: 1114339.4 | F7: 4328730.5

Sheet Comparative analysis
A1: Row Labels | B1: Average of Post Interaction Rate | C1: Sum of Total Engagement
A2: Instagram | B2: 13.154964 | C2: 1168239
A3: Carousel | B3: 13.961785 | C3: 343280
A4: Image | B4: 10.377515 | C4: 276109
A5: Tweet | B5: 13.337018 | C5: 258058
A6: Video | B6: 15.217795 | C6: 290792
A7: LinkedIn | B7: 13.775313 | C7: 1390876
A8: Carousel | B8: 12.250809 | C8: 312259
A9: Image | B9: 13.468316 | C9: 404925
A10: Tweet | B10: 12.666457 | C10: 341726
A11: Video | B11: 17.048993 | C11: 331966
A12: Twitter | B12: 15.15462 | C12: 1241294
A13: Carousel | B13: 15.497724 | C13: 471930
... A21: Video | B21: 14.13093 | C21: 354924
A22: (blank)
A23: (blank)
A24: Grand Total | B24: 13.613575 | C24: 4983122

Sheet Engagement vs ad spend as per p
A1: Sum of Engagement | B1: Column Labels
A2: Row Labels | B2: Instagram | C2: LinkedIn | D2: Twitter | E2: YouTube | F2: Grand Total
A3: 10161 | E3: 7579400 | F3: 7579400
A4: 10162 | E4: 14954400 | F4: 14954400
A5: 10541 | C5: 7784300 | F5: 7784300
A6: 11013 | B6: 2848900 | F6: 2848900
A7: 11171 | B7: 2484900 | F7: 2484900
A8: 11431 | C8: 9651600 | F8: 9651600
A9: 11619 | E9: 7799000 | F9: 7799000
A10: 11651 | E10: 12905200 | F10: 12905200
A11: 11828 | C11: 9181600 | F11: 9181600
A12: 12023 | D12: 5197100 | F12: 5197100
A13: 12096 | C13: 8622900 | F13: 8622900
A14: 12539 | D14: 13688800 | F14: 13688800
A15: 12563 | E15: 13277500 | F15: 13277500
A16: 12643 | E16: 6008500 | F16: 6008500
A17: 12839 | E17: 14925100 | F17: 14925100
A18: 13384 | D18: 5878100 | F18: 5878100
A19: 13390 | D19: 9908700 | F19: 9908700
A20: 13471 | B20: 1058700 | F20: 1058700
A21: 13586 | D21: 6782800 | F21: 6782800
A22: 15017 | C22: 13929500 | F22: 13929500
A23: 15105 | B23: 11293200 | F23: 11293200
A24: 15110 | B24: 1928300 | F24: 1928300
A25: 15347 | C25: 6630700 | F25: 6630700
A26: 15432 | C26: 3356700 | F26: 3356700
A27: 15469 | B27: 12045400 | F27: 12045400
A28: 15997 | C28: 4338000 | F28: 4338000
A29: 16256 | B29: 6440000 | F29: 6440000
A30: 16397 | C30: 11908900 | F30: 11908900
A31: 16643 | E31: 9544500 | F31: 9544500
A32: 17531 | D32: 13668800 | F32: 13668800
A33: 17710 | D33: 3274600 | F33: 3274600
A34: 17736 | E34: 8295400 | F34: 8295400
A35: 17896 | C35: 2394700 | F35: 2394700
A36: 17909 | C36: 2356500 | F36: 2356500
A37: 17927 | C37: 1825900 | F37: 1825900
A38: 17999 | B38: 1015500 | F38: 1015500
A39: 18329 | C39: 13098700 | F39: 13098700
A40: 18461 | C40: 6390900 | F40: 6390900
...

Sheet Frequently used hashtags
A1: Row Labels | B1: Count of Hashtags
A2: #AppleDesign #Innovation | B2: 25
A3: #AppleEvent #iPadPro | B3: 19
A4: #AppleEvent #iPhone16 | B4: 32
A5: #AppleMusic #AppleLifestyle | B5: 34
A6: #AppleWatch #Health | B6: 37
A7: #AppleWatchUltra2 #HealthTech | B7: 25
A8: #iPhone16Launch #AppleEvent | B8: 29
A9: #iPhonePhotography #ShotOniPhone | B9: 25
A10: #MacBookAirM3 #AppleInnovation | B10: 28
A11: #MacBookProM3 | B11: 17
A12: #ShotOniPhone | B12: 16
A13: #Sustainability #AppleEarth | B13: 13
A14: Grand Total | B14: 300

Sheet average performance of posts
A1: Row Labels | B1: Average of Comments | C1: Average of Likes | D1: Average of Shares
A2: #AppleDesign #Innovation | B2: 637.56 | C2: 13327.8 | D2: 892.8
A3: #AppleEvent #iPadPro | B3: 535.68421 | C3: 12987 | D3: 900.36842
A4: #AppleEvent #iPhone16 | B4: 567.59375 | C4: 14262.094 | D4: 869.34375
A5: #AppleMusic #AppleLifestyle | B5: 584.76471 | C5: 13437.176 | D5: 875.88235
A6: #AppleWatch #Health | B6: 576.91892 | C6: 13986.108 | D6: 880.54054
A7: #AppleWatchUltra2 #HealthTech | B7: 560.12 | C7: 13057.88 | D7: 980.64
A8: #iPhone16Launch #AppleEvent | B8: 541.13793 | C8: 15420.517 | D8: 803.65517
A9: #iPhonePhotography #ShotOniPhone | B9: 562.12 | C9: 13856.76 | D9: 802.2
A10: #MacBookAirM3 #AppleInnovation | B10: 531.75 | C10: 13015.321 | D10: 901.46429
A11: #MacBookProM3 | B11: 626.05882 | C11: 12777.235 | D11: 814.35294
A12: #ShotOniPhone | B12: 574.875 | C12: 14377.688 | D12: 806.5625
A13: #Sustainability #AppleEarth | B13: 646.23077 | C13: 9616.3077 | D13: 908.69231
A14: Grand Total | B14: 574.62667 | C14: 13558.143 | D14: 870.95333

Sheet Content Performance
A1: Row Labels | B1: Average of Likes | C1: Average of Shares | D1: Average of Comments
A2: Carousel | B2: 13039.913 | C2: 884.02174 | D2: 591.1087
A3: Image | B3: 13110.412 | C3: 839.61765 | D3: 574.45588
A4: Tweet | B4: 13363.406 | C4: 908.85507 | D4: 544.49275
A5: Video | B5: 14847.718 | C5: 847.19718 | D5: 582.71831
A6: Grand Total | B6: 13558.143 | C6: 870.95333 | D6: 574.62667

Sheet content type performs best
A1: Average of Total Engagement | B1: Column Labels
A2: Row Labels | B2: Carousel | C2: Image | D2: Tweet | E2: Video | F2: Grand Total
A3: Instagram | B3: 15603.636 | C3: 13805.45 | D3: 17203.867 | E3: 17105.412 | F3: 15787.014
A4: LinkedIn | B4: 15612.95 | C4: 16871.875 | D4: 17985.579 | E4: 18442.556 | F4: 17171.309
A5: Twitter | B5: 18151.154 | C5: 19335.556 | D5: 17037.889 | E5: 19244.133 | F5: 18254.324
A6: YouTube | B6: 14618.292 | C6: 15890.933 | D6: 14034.471 | E6: 16901.143 | F6: 15359.909
A7: Grand Total | B7: 16068.565 | C7: 16079.676 | D7: 16594.957 | E7: 17835.831 | F7: 16610.407
A10: Twitter image is best
A11: Linkedin Video is best
A12: Instagram Tweet is best
A13: Youtube video is best

Sheet content type performs best cont
A1: Platform | B1: ContentType | C1: Total Engagement
A2: YouTube | B2: Image | C2: 29141
A3: LinkedIn | B3: Image | C3: 7899
A4: Instagram | B4: Tweet | C4: 22920
A5: YouTube | B5: Video | C5: 6903
A6: YouTube | B6: Video | C6: 23673
A7: LinkedIn | B7: Image | C7: 16722
A8: Instagram | B8: Carousel | C8: 9041
A9: Instagram | B9: Video | C9: 22908
A10: YouTube | B10: Carousel | C10: 9656
A11: Twitter | B11: Video | C11: 22810
A12: YouTube | B12: Carousel | C12: 14979
A13: YouTube | B13: Tweet | C13: 5068
... A301: LinkedIn | B301: Video | C301: 23202

Sheet Total & Average Impressions
A1: Row Labels | B1: Sum of Impressions | C1: Average of Clicks | D1: Sum of Clicks | E1: Average of Likes | F1: Sum of Likes | G1: Average of Impressions
A2: Apple Event September 2025 | B2: 10331022 | C2: 1664.5507 | D2: 114854 | E2: 13870.29 | F2: 957050 | G2: 149724.96
A3: Apple Watch Ultra 2 Launch | B3: 9407749 | C3: 1547.4638 | D3: 106775 | E3: 12877.232 | F3: 888529 | G3: 136344.19
A4: iPhone 16 Launch | B4: 8901334 | C4: 1636.322 | D4: 96543 | E4: 14295.441 | F4: 843431 | G4: 150870.07
A5: MacBook Air M3 Campaign | B5: 6698763 | C5: 1623.1957 | D5: 74667 | E5: 12738.478 | F5: 585970 | G5: 145625.28
A6: Sustainability Awareness Drive | B6: 9222999 | C6: 1564.3158 | D6: 89166 | E6: 13902.86 | F6: 792463 | G6: 161807
A7: Grand Total | B7: 44561867 | C7: 1606.6833 | D7: 482005 | E7: 13558.143 | F7: 4067443 | G7: 148539.56

Sheet Analyse cost efficiency
A1: Row Labels | B1: Average of Engagement_Rate | C1: Average of Cost per new follower
A2: Instagram | B2: 15.559292 | C2: 8.892945
A3: LinkedIn | B3: 14.067998 | C3: 9.9250123
A4: Twitter | B4: 17.480513 | C4: 7.2249455
A5: YouTube | B5: 17.599263 | C5: 5.9447789
A6: Grand Total | B6: 16.076504 | C6: 8.1303696

Sheet Find out highest ROI
A1: Row Labels | B1: Sum of Engagement | C1: Sum of Ad_Spend | D1: ROI
A2: Apple Event September 2025 | B2: 1051098 | C2: 75000 | D2: =B2/C2 -> 14.01464
A3: Apple Watch Ultra 2 Launch | B3: 991433 | C3: 55000 | D3: =B3/C3 -> 18.026055
A4: iPhone 16 Launch | B4: 926462 | C4: 85000 | D4: =B4/C4 -> 10.899553
A5: MacBook Air M3 Campaign | B5: 652233 | C5: 60000 | D5: =B5/C5 -> 10.87055
A6: Sustainability Awareness Drive | B6: 879891 | C6: 40000 | D6: =B6/C6 -> 21.997275
C7: Sustainability Awareness Drive has highest ROI

Sheet Weekly folower growth platform
A1: Sum of Net followers | B1: Column Labels
A2: Row Labels | B2: Instagram | C2: LinkedIn | D2: Twitter | E2: YouTube | F2: (blank) | G2: Grand Total
A3: 2024-06-03 | B3: 3777 | D3: 7432 | E3: 15994 | G3: 27203
A4: 2024-06-10 | B4: 7215 | D4: 8369 | E4: 7478 | G4: 23062
A5: 2024-06-17 | B5: 13130 | C5: 6728 | D5: 6073 | G5: 25931
A6: 2024-06-24 | B6: 4885 | D6: 15084 | E6: 8653 | G6: 28622
A7: 2024-07-01 | B7: 5928 | C7: 5442 | D7: 8463 | G7: 19833
A8: 2024-07-08 | C8: 11378 | D8: 7151 | G8: 18529
A9: 2024-07-15 | B9: 4967 | D9: 7092 | E9: 1826 | G9: 13885
A10: 2024-07-22 | C10: 15403 | D10: 7733 | E10: 9082 | G10: 32218
A11: 2024-07-29 | C11: 7537 | D11: 6039 | E11: 3445 | G11: 17021
A12: 2024-08-05 | B12: 3213 | C12: 4847 | D12: 3497 | E12: 2543 | G12: 14100
A13: 2024-08-12 | B13: 6853 | D13: 12800 | E13: 7033 | G13: 26686
A14: 2024-08-19 | B14: 13835 | E14: 9427 | G14: 23262
A15: 2024-08-26 | B15: 8231 | C15: 1513 | D15: 5753 | E15: 5303 | G15: 20800
A16: 2024-09-02 | B16: 7396 | C16: 8228 | D16: 6593 | G16: 22217
A17: 2024-09-09 | B17: 7442 | C17: 6121 | E17: 11613 | G17: 25176
A18: 2024-09-16 | C18: 2199 | D18: 3925 | E18: 9308 | G18: 15432
A19: 2024-09-23 | B19: 13040 | D19: 4942 | G19: 17982
A20: 2024-09-30 | B20: 9904 | D20: 8530 | G20: 18434
A21: 2024-10-07 | B21: 4808 | C21: 2421 | E21: 10348 | G21: 17577
A22: 2024-10-14 | D22: 16256 | E22: 7115 | G22: 23371
A23: 2024-10-21 | B23: 23973 | E23: 6918 | G23: 30891
A24: 2024-10-28 | C24: 14812 | E24: 12442 | G24: 27254
A25: 2024-11-04 | C25: 4942 | D25: 8687 | E25: 3056 | G25: 16685
A26: 2024-11-11 | C26: 4882 | D26: 9649 | E26: 5220 | G26: 19751
A27: 2024-11-18 | B27: 5206 | C27: 9648 | D27: 6384 | G27: 21238
A28: 2024-11-25 | B28: 14537 | C28: 8945 | E28: 5143 | G28: 28625
A29: 2024-12-02 | B29: 8999 | C29: 5402 | E29: 3929 | G29: 18330
A30: 2024-12-09 | B30: 3461 | C30: 949 | D30: 6642 | E30: 4790 | G30: 15842
A31: 2024-12-16 | B31: 4802 | C31: 8527 | D31: 6275 | G31: 19604
A32: 2024-12-23 | B32: 4314 | C32: 7541 | E32: 7328 | G32: 19183
A33: 2024-12-30 | B33: 4214 | C33: 16577 | D33: 3079 | G33: 23870
A34: 2025-01-06 | C34: 9254 | D34: 9202 | E34: 8601 | G34: 27057
A35: 2025-01-13 | B35: 2919 | C35: 7471 | D35: 7346 | E35: 1001 | G35: 18737
A36: 2025-01-20 | D36: 20155 | E36: 7654 | G36: 27809
A37: 2025-01-27 | B37: 3643 | C37: 7260 | D37: 11789 | G37: 22692
A38: 2025-02-03 | D38: 16086 | E38: 12447 | G38: 28533
A39: 2025-02-10 | C39: 12622 | D39: 1020 | G39: 13642
A40: 2025-02-17 | B40: 11468 | C40: 5101 | D40: 1290 | G40: 17859
...

Sheet The peak of week of follower ga
A1: Row Labels | B1: Sum of New_Followers
A2: 2024-06-03 | B2: 30937
A3: 2024-06-10 | B3: 24926
A4: 2024-06-17 | B4: 29033
A5: 2024-06-24 | B5: 31430
A6: 2024-07-01 | B6: 21836
A7: 2024-07-08 | B7: 20394
A8: 2024-07-15 | B8: 15600
A9: 2024-07-22 | B9: 35220
A10: 2024-07-29 | B10: 19605
A11: 2024-08-05 | B11: 15446
A12: 2024-08-12 | B12: 29373
A13: 2024-08-19 | B13: 25600
... A17: 2024-09-16 | B17: 17005
A18: 2024-09-23 | B18: 20095 | F18: =MAX(B2:B51) -> 35220
A19: 2024-09-30 | B19: 20374 | F19: =INDEX(A2:A51,MATCH(MAX(B2:B51),B2:B51,0)) -> 2024-07-22
A20: 2024-10-07 | B20: 19886
A21: 2024-10-14 | B21: 25576
A22: 2024-10-21 | B22: 34182
A23: 2024-10-28 | B23: 30338
A24: 2024-11-04 | B24: 18704
A25: 2024-11-11 | B25: 22206
A26: 2024-11-18 | B26: 23076
A27: 2024-11-25 | B27: 31244
A28: 2024-12-02 | B28: 20319
A29: 2024-12-09 | B29: 17052
A30: 2024-12-16 | B30: 22471
A31: 2024-12-23 | B31: 21551
... A52: Grand Total | B52: 1205188

Sheet Use moving averages to smooth 
A1: Date | B1: Instagram | C1: LinkedIn | D1: Twitter | E1: YouTube | F1: Instagram 4W_MA | G1: LinkedIn 4W_MA | H1: Twitter 4W_MA | I1: YouTube 4W_MA
A2: 2024-06-03 | B2: 3777 | D2: 7432 | E2: 15994 | F2: 7251.75 | G2: 6728 | H2: 9239.5 | I2: 10708.333
A3: 2024-06-10 | B3: 7215 | D3: 8369 | E3: 7478 | F3: 7789.5 | G3: 6085 | H3: 9497.25 | I3: 8065.5
A4: 2024-06-17 | B4: 13130 | C4: 6728 | D4: 6073 | F4: 7981 | G4: 7849.3333 | H4: 9192.75 | I4: 8653
A5: 2024-06-24 | B5: 4885 | D5: 15084 | E5: 8653 | F5: 5260 | G5: 8410 | H5: 9447.5 | I5: 5239.5
A6: 2024-07-01 | B6: 5928 | C6: 5442 | D6: 8463 | F6: 5447.5 | G6: 10741 | H6: 7609.75 | I6: 5454
A7: 2024-07-08 | C7: 11378 | D7: 7151 | F7: 4967 | G7: 11439.333 | H7: 7003.75 | I7: 4784.3333
A8: 2024-07-15 | B8: 4967 | D8: 7092 | E8: 1826 | F8: 4090 | G8: 9262.3333 | H8: 6090.25 | I8: 4224
A9: 2024-07-22 | C9: 15403 | D9: 7733 | E9: 9082 | F9: 5033 | G9: 9262.3333 | H9: 7517.25 | I9: 5525.75
A10: 2024-07-29 | C10: 7537 | D10: 6039 | E10: 3445 | F10: 7967 | G10: 6192 | H10: 7445.3333 | I10: 5612
A11: 2024-08-05 | B11: 3213 | C11: 4847 | D11: 3497 | E11: 2543 | F11: 8033 | G11: 3180 | H11: 7350 | I11: 6076.5
A12: 2024-08-12 | B12: 6853 | D12: 12800 | E12: 7033 | F12: 9078.75 | G12: 4870.5 | H12: 8382 | I12: 7254.3333
A13: 2024-08-19 | B13: 13835 | E13: 9427 | F13: 9226 | G13: 5287.3333 | H13: 6173 | I13: 8781
A14: 2024-08-26 | B14: 8231 | C14: 1513 | D14: 5753 | E14: 5303 | F14: 7689.6667 | G14: 4515.25 | H14: 5423.6667 | I14: 8741.3333
A15: 2024-09-02 | B15: 7396 | C15: 8228 | D15: 6593 | F15: 9292.6667 | G15: 5516 | H15: 5153.3333 | I15: 10460.5
A16: 2024-09-09 | B16: 7442 | C16: 6121 | E16: 11613 | F16: 10128.667 | G16: 4160 | H16: 5799 | I16: 10460.5
A17: 2024-09-16 | C17: 2199 | D17: 3925 | E17: 9308 | F17: 9250.6667 | G17: 2310 | H17: 5799 | I17: 9828
A18: 2024-09-23 | B18: 13040 | D18: 4942 | F18: 9250.6667 | G18: 2421 | H18: 9909.3333 | I18: 8731.5
A19: 2024-09-30 | B19: 9904 | D19: 8530 | F19: 12895 | G19: 2421 | H19: 12393 | I19: 8127
A20: 2024-10-07 | B20: 4808 | C20: 2421 | E20: 10348 | F20: 14390.5 | G20: 8616.5 | H20: 16256 | I20: 9205.75
A21: 2024-10-14 | D21: 16256 | E21: 7115 | F21: 23973 | G21: 9877 | H21: 12471.5 | I21: 7382.75
A22: 2024-10-21 | B22: 23973 | E22: 6918 | F22: 23973 | G22: 8212 | H22: 9168 | I22: 6909
A23: 2024-10-28 | C23: 14812 | E23: 12442 | F23: 5206 | G23: 8571 | H23: 8240 | I23: 6906
A24: 2024-11-04 | C24: 4942 | D24: 8687 | E24: 3056 | F24: 9871.5 | G24: 7104.25 | H24: 8240 | I24: 4473
A25: 2024-11-11 | C25: 4882 | D25: 9649 | E25: 5220 | F25: 9580.6667 | G25: 7219.25 | H25: 8016.5 | I25: 4764
A26: 2024-11-18 | B26: 5206 | C26: 9648 | D26: 6384 | F26: 8050.75 | G26: 6236 | H26: 6513 | I26: 4620.6667
A27: 2024-11-25 | B27: 14537 | C27: 8945 | E27: 5143 | F27: 7949.75 | G27: 5955.75 | H27: 6458.5 | I27: 4620.6667
A28: 2024-12-02 | B28: 8999 | C28: 5402 | E28: 3929 | F28: 5394 | G28: 5604.75 | H28: 6458.5 | I28: 5349
A29: 2024-12-09 | B29: 3461 | C29: 949 | D29: 6642 | E29: 4790 | F29: 4197.75 | G29: 8398.5 | H29: 5332 | I29: 6059
A30: 2024-12-16 | B30: 4802 | C30: 8527 | D30: 6275 | F30: 4443.3333 | G30: 10474.75 | H30: 6185.3333 | I30: 7964.5
A31: 2024-12-23 | B31: 4314 | C31: 7541 | E31: 7328 | F31: 3815.6667 | G31: 10210.75 | H31: 6542.3333 | I31: 5643.3333
A32: 2024-12-30 | B32: 4214 | C32: 16577 | D32: 3079 | F32: 3566.5 | G32: 11100.667 | H32: 9945.5 | I32: 5752
A33: 2025-01-06 | C33: 9254 | D33: 9202 | E33: 8601 | F33: 3281 | G33: 7995 | H33: 12123 | I33: 5752
A34: 2025-01-13 | B34: 2919 | C34: 7471 | D34: 7346 | E34: 1001 | F34: 3281 | G34: 7365.5 | H34: 13844 | I34: 7034
A35: 2025-01-20 | D35: 20155 | E35: 7654 | F35: 3643 | G35: 9941 | H35: 12262.5 | I35: 10050.5
A36: 2025-01-27 | B36: 3643 | C36: 7260 | D36: 11789 | F36: 7555.5 | G36: 8327.6667 | H36: 7546.25 | I36: 12447
A37: 2025-02-03 | D37: 16086 | E37: 12447 | F37: 13277.5 | G37: 8861.5 | H37: 6132 | I37: 13903
A38: 2025-02-10 | C38: 12622 | D38: 1020 | F38: 13277.5 | G38: 8385 | H38: 2878.6667 | I38: 10995
A39: 2025-02-17 | B39: 11468 | C39: 5101 | D39: 1290 | F39: 9849.6667 | G39: 5022.6667 | H39: 5446.3333 | I39: 8515
A40: 2025-02-24 | B40: 15087 | E40: 15359 | F40: 8791 | G40: 9898.3333 | H40: 7524.5 | I40: 8515
...

Sheet ads spend vs follower grow scat
A1: Sum of Net followers | B1: Sum of Ad_Spend
A2: 27203 | B2: 138117
A3: 23062 | B3: 150962
A4: 25931 | B4: 98040
A5: 28622 | B5: 164565
A6: 19833 | B6: 156343
A7: 18529 | B7: 111798
A8: 13885 | B8: 96330
A9: 32218 | B9: 165690
A10: 17021 | B10: 149979
A11: 14100 | B11: 137738
A12: 26686 | B12: 127141
A13: 23262 | B13: 131436
... A51: 18387 | B51: 153197

Sheet Sum of ROI
A1: Row Labels | B1: Sum of ROI
A2: Instagram | B2: 11586.754
A3: LinkedIn | B3: 16142.629
A4: Twitter | B4: 14152.261
A5: YouTube | B5: 14512.807
A6: Grand Total | B6: 56394.451

Sheet Dum of total folowers and unfol
A1: Row Labels | B1: Sum of Total_Followers | C1: Sum of Unfollows
A2: 2024-06-03 | B2: 461521 | C2: 3734
A3: 2024-06-10 | B3: 573409 | C3: 1864
A4: 2024-06-17 | B4: 668221 | C4: 3102
A5: 2024-06-24 | B5: 777791 | C5: 2808
A6: 2024-07-01 | B6: 875559 | C6: 2003
A7: 2024-07-08 | B7: 948658 | C7: 1865
A8: 2024-07-15 | B8: 1013373 | C8: 1715
A9: 2024-07-22 | B9: 1106205 | C9: 3002
A10: 2024-07-29 | B10: 1194413 | C10: 2584
A11: 2024-08-05 | B11: 1258492 | C11: 1346
A12: 2024-08-12 | B12: 1346426 | C12: 2687
A13: 2024-08-19 | B13: 1449439 | C13: 2338
... A52: Grand Total | B52: 130681544 | C52: 118790

Sheet Pivot Table
A1: Row Labels | B1: Sum of Net followers | C1: Sum of Ad_Spend
A2: 2024-06-03 | B2: 27203 | C2: 138117
A3: 2024-06-10 | B3: 23062 | C3: 150962
A4: 2024-06-17 | B4: 25931 | C4: 98040
A5: 2024-06-24 | B5: 28622 | C5: 164565
A6: 2024-07-01 | B6: 19833 | C6: 156343
A7: 2024-07-08 | B7: 18529 | C7: 111798
A8: 2024-07-15 | B8: 13885 | C8: 96330
A9: 2024-07-22 | B9: 32218 | C9: 165690
A10: 2024-07-29 | B10: 17021 | C10: 149979
A11: 2024-08-05 | B11: 14100 | C11: 137738
A12: 2024-08-12 | B12: 26686 | C12: 127141
A13: 2024-08-19 | B13: 23262 | C13: 131436
... A51: 2025-05-12 | B51: 18387 | C51: 153197
A52: (blank)
A53: Grand Total | B53: 1086398 | C53: 6926860
